2021-02-26 15:17:30,282 ERROR: Exception on /user/userA [GET] [in /Users/markgetrost/.pyenv/versions/3.9.0/envs/venv390/lib/python3.9/site-packages/flask/app.py:1891]
Traceback (most recent call last):
  File "/Users/markgetrost/.pyenv/versions/3.9.0/envs/venv390/lib/python3.9/site-packages/sqlalchemy/engine/base.py", line 1276, in _execute_context
    self.dialect.do_execute(
  File "/Users/markgetrost/.pyenv/versions/3.9.0/envs/venv390/lib/python3.9/site-packages/sqlalchemy/engine/default.py", line 608, in do_execute
    cursor.execute(statement, parameters)
sqlite3.OperationalError: no such table: followers

The above exception was the direct cause of the following exception:

Traceback (most recent call last):
  File "/Users/markgetrost/.pyenv/versions/3.9.0/envs/venv390/lib/python3.9/site-packages/flask/app.py", line 2447, in wsgi_app
    response = self.full_dispatch_request()
  File "/Users/markgetrost/.pyenv/versions/3.9.0/envs/venv390/lib/python3.9/site-packages/flask/app.py", line 1952, in full_dispatch_request
    rv = self.handle_user_exception(e)
  File "/Users/markgetrost/.pyenv/versions/3.9.0/envs/venv390/lib/python3.9/site-packages/flask/app.py", line 1821, in handle_user_exception
    reraise(exc_type, exc_value, tb)
  File "/Users/markgetrost/.pyenv/versions/3.9.0/envs/venv390/lib/python3.9/site-packages/flask/_compat.py", line 39, in reraise
    raise value
  File "/Users/markgetrost/.pyenv/versions/3.9.0/envs/venv390/lib/python3.9/site-packages/flask/app.py", line 1950, in full_dispatch_request
    rv = self.dispatch_request()
  File "/Users/markgetrost/.pyenv/versions/3.9.0/envs/venv390/lib/python3.9/site-packages/flask/app.py", line 1936, in dispatch_request
    return self.view_functions[rule.endpoint](**req.view_args)
  File "/Users/markgetrost/.pyenv/versions/3.9.0/envs/venv390/lib/python3.9/site-packages/flask_login/utils.py", line 272, in decorated_view
    return func(*args, **kwargs)
  File "/Users/markgetrost/Projects/FlaskMega/firstwebapp/app/routes.py", line 87, in user
    return render_template('user.html',user=user,posts=posts,form=form)
  File "/Users/markgetrost/.pyenv/versions/3.9.0/envs/venv390/lib/python3.9/site-packages/flask/templating.py", line 137, in render_template
    return _render(
  File "/Users/markgetrost/.pyenv/versions/3.9.0/envs/venv390/lib/python3.9/site-packages/flask/templating.py", line 120, in _render
    rv = template.render(context)
  File "/Users/markgetrost/.pyenv/versions/3.9.0/envs/venv390/lib/python3.9/site-packages/jinja2/environment.py", line 1090, in render
    self.environment.handle_exception()
  File "/Users/markgetrost/.pyenv/versions/3.9.0/envs/venv390/lib/python3.9/site-packages/jinja2/environment.py", line 832, in handle_exception
    reraise(*rewrite_traceback_stack(source=source))
  File "/Users/markgetrost/.pyenv/versions/3.9.0/envs/venv390/lib/python3.9/site-packages/jinja2/_compat.py", line 28, in reraise
    raise value.with_traceback(tb)
  File "/Users/markgetrost/Projects/FlaskMega/firstwebapp/app/templates/user.html", line 1, in top-level template code
    {% extends "base.html" %}
  File "/Users/markgetrost/Projects/FlaskMega/firstwebapp/app/templates/base.html", line 32, in top-level template code
    {% block content %}{% endblock %}
  File "/Users/markgetrost/Projects/FlaskMega/firstwebapp/app/templates/user.html", line 19, in block "content"
    {% elif not current_user.is_following(user) %}
  File "/Users/markgetrost/Projects/FlaskMega/firstwebapp/app/models.py", line 105, in is_following
    return self.followed.filter(followers.c.followed_id==user.id).count() > 0
  File "/Users/markgetrost/.pyenv/versions/3.9.0/envs/venv390/lib/python3.9/site-packages/sqlalchemy/orm/query.py", line 3803, in count
    return self.from_self(col).scalar()
  File "/Users/markgetrost/.pyenv/versions/3.9.0/envs/venv390/lib/python3.9/site-packages/sqlalchemy/orm/query.py", line 3523, in scalar
    ret = self.one()
  File "/Users/markgetrost/.pyenv/versions/3.9.0/envs/venv390/lib/python3.9/site-packages/sqlalchemy/orm/query.py", line 3490, in one
    ret = self.one_or_none()
  File "/Users/markgetrost/.pyenv/versions/3.9.0/envs/venv390/lib/python3.9/site-packages/sqlalchemy/orm/query.py", line 3459, in one_or_none
    ret = list(self)
  File "/Users/markgetrost/.pyenv/versions/3.9.0/envs/venv390/lib/python3.9/site-packages/sqlalchemy/orm/query.py", line 3535, in __iter__
    return self._execute_and_instances(context)
  File "/Users/markgetrost/.pyenv/versions/3.9.0/envs/venv390/lib/python3.9/site-packages/sqlalchemy/orm/query.py", line 3560, in _execute_and_instances
    result = conn.execute(querycontext.statement, self._params)
  File "/Users/markgetrost/.pyenv/versions/3.9.0/envs/venv390/lib/python3.9/site-packages/sqlalchemy/engine/base.py", line 1011, in execute
    return meth(self, multiparams, params)
  File "/Users/markgetrost/.pyenv/versions/3.9.0/envs/venv390/lib/python3.9/site-packages/sqlalchemy/sql/elements.py", line 298, in _execute_on_connection
    return connection._execute_clauseelement(self, multiparams, params)
  File "/Users/markgetrost/.pyenv/versions/3.9.0/envs/venv390/lib/python3.9/site-packages/sqlalchemy/engine/base.py", line 1124, in _execute_clauseelement
    ret = self._execute_context(
  File "/Users/markgetrost/.pyenv/versions/3.9.0/envs/venv390/lib/python3.9/site-packages/sqlalchemy/engine/base.py", line 1316, in _execute_context
    self._handle_dbapi_exception(
  File "/Users/markgetrost/.pyenv/versions/3.9.0/envs/venv390/lib/python3.9/site-packages/sqlalchemy/engine/base.py", line 1510, in _handle_dbapi_exception
    util.raise_(
  File "/Users/markgetrost/.pyenv/versions/3.9.0/envs/venv390/lib/python3.9/site-packages/sqlalchemy/util/compat.py", line 182, in raise_
    raise exception
  File "/Users/markgetrost/.pyenv/versions/3.9.0/envs/venv390/lib/python3.9/site-packages/sqlalchemy/engine/base.py", line 1276, in _execute_context
    self.dialect.do_execute(
  File "/Users/markgetrost/.pyenv/versions/3.9.0/envs/venv390/lib/python3.9/site-packages/sqlalchemy/engine/default.py", line 608, in do_execute
    cursor.execute(statement, parameters)
sqlalchemy.exc.OperationalError: (sqlite3.OperationalError) no such table: followers
[SQL: SELECT count(*) AS count_1 
FROM (SELECT user.id AS user_id, user.username AS user_username, user.email AS user_email, user.password_hash AS user_password_hash, user.about_me AS user_about_me, user.last_seen AS user_last_seen 
FROM user, followers 
WHERE followers.follower_id = ? AND followers.followed_id = user.id AND followers.followed_id = ?) AS anon_1]
[parameters: (6, 4)]
(Background on this error at: http://sqlalche.me/e/13/e3q8)
2021-02-26 15:19:51,504 INFO: Microblog startup [in /Users/markgetrost/Projects/FlaskMega/firstwebapp/app/__init__.py:54]
2021-02-26 15:21:14,261 INFO: Microblog startup [in /Users/markgetrost/Projects/FlaskMega/firstwebapp/app/__init__.py:54]
2021-02-26 15:32:15,475 INFO: Microblog startup [in /Users/markgetrost/Projects/FlaskMega/firstwebapp/app/__init__.py:54]
2021-02-26 15:34:35,129 INFO: Microblog startup [in /Users/markgetrost/Projects/FlaskMega/firstwebapp/app/__init__.py:54]
2021-02-26 15:45:17,324 INFO: Microblog startup [in /Users/markgetrost/Projects/FlaskMega/firstwebapp/app/__init__.py:54]
2021-02-26 15:54:56,476 INFO: Microblog startup [in /Users/markgetrost/Projects/FlaskMega/firstwebapp/app/__init__.py:54]
2021-02-26 15:55:11,704 INFO: Microblog startup [in /Users/markgetrost/Projects/FlaskMega/firstwebapp/app/__init__.py:54]
