2021-02-27 17:58:38,738 ERROR: Exception on /index [GET] [in /Users/markgetrost/.pyenv/versions/3.9.0/envs/venv390/lib/python3.9/site-packages/flask/app.py:1891]
Traceback (most recent call last):
  File "/Users/markgetrost/.pyenv/versions/3.9.0/envs/venv390/lib/python3.9/site-packages/flask/app.py", line 2447, in wsgi_app
    response = self.full_dispatch_request()
  File "/Users/markgetrost/.pyenv/versions/3.9.0/envs/venv390/lib/python3.9/site-packages/flask/app.py", line 1952, in full_dispatch_request
    rv = self.handle_user_exception(e)
  File "/Users/markgetrost/.pyenv/versions/3.9.0/envs/venv390/lib/python3.9/site-packages/flask/app.py", line 1821, in handle_user_exception
    reraise(exc_type, exc_value, tb)
  File "/Users/markgetrost/.pyenv/versions/3.9.0/envs/venv390/lib/python3.9/site-packages/flask/_compat.py", line 39, in reraise
    raise value
  File "/Users/markgetrost/.pyenv/versions/3.9.0/envs/venv390/lib/python3.9/site-packages/flask/app.py", line 1950, in full_dispatch_request
    rv = self.dispatch_request()
  File "/Users/markgetrost/.pyenv/versions/3.9.0/envs/venv390/lib/python3.9/site-packages/flask/app.py", line 1936, in dispatch_request
    return self.view_functions[rule.endpoint](**req.view_args)
  File "/Users/markgetrost/.pyenv/versions/3.9.0/envs/venv390/lib/python3.9/site-packages/flask_login/utils.py", line 272, in decorated_view
    return func(*args, **kwargs)
  File "/Users/markgetrost/Projects/FlaskMega/firstwebapp/app/routes.py", line 65, in index
    return render_template('index.html', title='Home', form=form,
  File "/Users/markgetrost/.pyenv/versions/3.9.0/envs/venv390/lib/python3.9/site-packages/flask/templating.py", line 137, in render_template
    return _render(
  File "/Users/markgetrost/.pyenv/versions/3.9.0/envs/venv390/lib/python3.9/site-packages/flask/templating.py", line 120, in _render
    rv = template.render(context)
  File "/Users/markgetrost/.pyenv/versions/3.9.0/envs/venv390/lib/python3.9/site-packages/jinja2/environment.py", line 1090, in render
    self.environment.handle_exception()
  File "/Users/markgetrost/.pyenv/versions/3.9.0/envs/venv390/lib/python3.9/site-packages/jinja2/environment.py", line 832, in handle_exception
    reraise(*rewrite_traceback_stack(source=source))
  File "/Users/markgetrost/.pyenv/versions/3.9.0/envs/venv390/lib/python3.9/site-packages/jinja2/_compat.py", line 28, in reraise
    raise value.with_traceback(tb)
  File "/Users/markgetrost/Projects/FlaskMega/firstwebapp/app/templates/index.html", line 1, in top-level template code
    {% extends "base.html" %}
  File "/Users/markgetrost/Projects/FlaskMega/firstwebapp/app/templates/base.html", line 22, in top-level template code
    <a href="{{ url_for('break')}}">Break</a>
  File "/Users/markgetrost/.pyenv/versions/3.9.0/envs/venv390/lib/python3.9/site-packages/flask/helpers.py", line 370, in url_for
    return appctx.app.handle_url_build_error(error, endpoint, values)
  File "/Users/markgetrost/.pyenv/versions/3.9.0/envs/venv390/lib/python3.9/site-packages/flask/app.py", line 2216, in handle_url_build_error
    reraise(exc_type, exc_value, tb)
  File "/Users/markgetrost/.pyenv/versions/3.9.0/envs/venv390/lib/python3.9/site-packages/flask/_compat.py", line 39, in reraise
    raise value
  File "/Users/markgetrost/.pyenv/versions/3.9.0/envs/venv390/lib/python3.9/site-packages/flask/helpers.py", line 357, in url_for
    rv = url_adapter.build(
  File "/Users/markgetrost/.pyenv/versions/3.9.0/envs/venv390/lib/python3.9/site-packages/werkzeug/routing.py", line 2179, in build
    raise BuildError(endpoint, values, method, self)
werkzeug.routing.BuildError: Could not build url for endpoint 'break'. Did you mean 'explore' instead?
2021-02-27 18:02:17,478 INFO: Microblog startup [in /Users/markgetrost/Projects/FlaskMega/firstwebapp/app/__init__.py:58]
2021-02-27 18:02:21,081 ERROR: Exception on /index [GET] [in /Users/markgetrost/.pyenv/versions/3.9.0/envs/venv390/lib/python3.9/site-packages/flask/app.py:1891]
Traceback (most recent call last):
  File "/Users/markgetrost/.pyenv/versions/3.9.0/envs/venv390/lib/python3.9/site-packages/flask/app.py", line 2447, in wsgi_app
    response = self.full_dispatch_request()
  File "/Users/markgetrost/.pyenv/versions/3.9.0/envs/venv390/lib/python3.9/site-packages/flask/app.py", line 1952, in full_dispatch_request
    rv = self.handle_user_exception(e)
  File "/Users/markgetrost/.pyenv/versions/3.9.0/envs/venv390/lib/python3.9/site-packages/flask/app.py", line 1821, in handle_user_exception
    reraise(exc_type, exc_value, tb)
  File "/Users/markgetrost/.pyenv/versions/3.9.0/envs/venv390/lib/python3.9/site-packages/flask/_compat.py", line 39, in reraise
    raise value
  File "/Users/markgetrost/.pyenv/versions/3.9.0/envs/venv390/lib/python3.9/site-packages/flask/app.py", line 1950, in full_dispatch_request
    rv = self.dispatch_request()
  File "/Users/markgetrost/.pyenv/versions/3.9.0/envs/venv390/lib/python3.9/site-packages/flask/app.py", line 1936, in dispatch_request
    return self.view_functions[rule.endpoint](**req.view_args)
  File "/Users/markgetrost/.pyenv/versions/3.9.0/envs/venv390/lib/python3.9/site-packages/flask_login/utils.py", line 272, in decorated_view
    return func(*args, **kwargs)
  File "/Users/markgetrost/Projects/FlaskMega/firstwebapp/app/routes.py", line 65, in index
    return render_template('index.html', title='Home', form=form,
  File "/Users/markgetrost/.pyenv/versions/3.9.0/envs/venv390/lib/python3.9/site-packages/flask/templating.py", line 137, in render_template
    return _render(
  File "/Users/markgetrost/.pyenv/versions/3.9.0/envs/venv390/lib/python3.9/site-packages/flask/templating.py", line 120, in _render
    rv = template.render(context)
  File "/Users/markgetrost/.pyenv/versions/3.9.0/envs/venv390/lib/python3.9/site-packages/jinja2/environment.py", line 1090, in render
    self.environment.handle_exception()
  File "/Users/markgetrost/.pyenv/versions/3.9.0/envs/venv390/lib/python3.9/site-packages/jinja2/environment.py", line 832, in handle_exception
    reraise(*rewrite_traceback_stack(source=source))
  File "/Users/markgetrost/.pyenv/versions/3.9.0/envs/venv390/lib/python3.9/site-packages/jinja2/_compat.py", line 28, in reraise
    raise value.with_traceback(tb)
  File "/Users/markgetrost/Projects/FlaskMega/firstwebapp/app/templates/index.html", line 1, in top-level template code
    {% extends "base.html" %}
  File "/Users/markgetrost/Projects/FlaskMega/firstwebapp/app/templates/base.html", line 22, in top-level template code
    <a href="{{ url_for('break')}}">Break</a>
  File "/Users/markgetrost/.pyenv/versions/3.9.0/envs/venv390/lib/python3.9/site-packages/flask/helpers.py", line 370, in url_for
    return appctx.app.handle_url_build_error(error, endpoint, values)
  File "/Users/markgetrost/.pyenv/versions/3.9.0/envs/venv390/lib/python3.9/site-packages/flask/app.py", line 2216, in handle_url_build_error
    reraise(exc_type, exc_value, tb)
  File "/Users/markgetrost/.pyenv/versions/3.9.0/envs/venv390/lib/python3.9/site-packages/flask/_compat.py", line 39, in reraise
    raise value
  File "/Users/markgetrost/.pyenv/versions/3.9.0/envs/venv390/lib/python3.9/site-packages/flask/helpers.py", line 357, in url_for
    rv = url_adapter.build(
  File "/Users/markgetrost/.pyenv/versions/3.9.0/envs/venv390/lib/python3.9/site-packages/werkzeug/routing.py", line 2179, in build
    raise BuildError(endpoint, values, method, self)
werkzeug.routing.BuildError: Could not build url for endpoint 'break'. Did you mean 'break_app' instead?
2021-02-27 18:02:33,499 INFO: Microblog startup [in /Users/markgetrost/Projects/FlaskMega/firstwebapp/app/__init__.py:58]
