2021-02-27 18:19:50,657 ERROR: Exception on /break_app [GET] [in /Users/markgetrost/.pyenv/versions/3.9.0/envs/venv390/lib/python3.9/site-packages/flask/app.py:1891]
Traceback (most recent call last):
  File "/Users/markgetrost/.pyenv/versions/3.9.0/envs/venv390/lib/python3.9/site-packages/flask/app.py", line 2447, in wsgi_app
    response = self.full_dispatch_request()
  File "/Users/markgetrost/.pyenv/versions/3.9.0/envs/venv390/lib/python3.9/site-packages/flask/app.py", line 1953, in full_dispatch_request
    return self.finalize_request(rv)
  File "/Users/markgetrost/.pyenv/versions/3.9.0/envs/venv390/lib/python3.9/site-packages/flask/app.py", line 1968, in finalize_request
    response = self.make_response(rv)
  File "/Users/markgetrost/.pyenv/versions/3.9.0/envs/venv390/lib/python3.9/site-packages/flask/app.py", line 2097, in make_response
    raise TypeError(
TypeError: The view function did not return a valid response. The function either returned None or ended without a return statement.
2021-02-27 18:23:38,930 INFO: Microblog startup [in /Users/markgetrost/Projects/FlaskMega/firstwebapp/app/__init__.py:58]
2021-02-27 18:24:08,237 INFO: Microblog startup [in /Users/markgetrost/Projects/FlaskMega/firstwebapp/app/__init__.py:58]
2021-02-27 18:28:48,878 INFO: Microblog startup [in /Users/markgetrost/Projects/FlaskMega/firstwebapp/app/__init__.py:58]
2021-02-27 18:34:47,031 INFO: Microblog startup [in /Users/markgetrost/Projects/FlaskMega/firstwebapp/app/__init__.py:58]
2021-02-27 18:36:45,934 INFO: Microblog startup [in /Users/markgetrost/Projects/FlaskMega/firstwebapp/app/__init__.py:58]
2021-02-27 18:36:52,229 ERROR: Exception on /break_app [GET] [in /Users/markgetrost/.pyenv/versions/3.9.0/envs/venv390/lib/python3.9/site-packages/flask/app.py:1891]
Traceback (most recent call last):
  File "/Users/markgetrost/.pyenv/versions/3.9.0/envs/venv390/lib/python3.9/site-packages/flask/app.py", line 2447, in wsgi_app
    response = self.full_dispatch_request()
  File "/Users/markgetrost/.pyenv/versions/3.9.0/envs/venv390/lib/python3.9/site-packages/flask/app.py", line 1953, in full_dispatch_request
    return self.finalize_request(rv)
  File "/Users/markgetrost/.pyenv/versions/3.9.0/envs/venv390/lib/python3.9/site-packages/flask/app.py", line 1968, in finalize_request
    response = self.make_response(rv)
  File "/Users/markgetrost/.pyenv/versions/3.9.0/envs/venv390/lib/python3.9/site-packages/flask/app.py", line 2097, in make_response
    raise TypeError(
TypeError: The view function did not return a valid response. The function either returned None or ended without a return statement.
2021-02-27 18:37:16,388 ERROR: Exception on /break_app [GET] [in /Users/markgetrost/.pyenv/versions/3.9.0/envs/venv390/lib/python3.9/site-packages/flask/app.py:1891]
Traceback (most recent call last):
  File "/Users/markgetrost/.pyenv/versions/3.9.0/envs/venv390/lib/python3.9/site-packages/flask/app.py", line 2447, in wsgi_app
    response = self.full_dispatch_request()
  File "/Users/markgetrost/.pyenv/versions/3.9.0/envs/venv390/lib/python3.9/site-packages/flask/app.py", line 1953, in full_dispatch_request
    return self.finalize_request(rv)
  File "/Users/markgetrost/.pyenv/versions/3.9.0/envs/venv390/lib/python3.9/site-packages/flask/app.py", line 1968, in finalize_request
    response = self.make_response(rv)
  File "/Users/markgetrost/.pyenv/versions/3.9.0/envs/venv390/lib/python3.9/site-packages/flask/app.py", line 2097, in make_response
    raise TypeError(
TypeError: The view function did not return a valid response. The function either returned None or ended without a return statement.
2021-02-27 19:05:09,331 INFO: Microblog startup [in /Users/markgetrost/Projects/FlaskMega/firstwebapp/app/__init__.py:58]
2021-02-27 19:05:24,466 ERROR: Exception on /break_app [GET] [in /Users/markgetrost/.pyenv/versions/3.9.0/envs/venv390/lib/python3.9/site-packages/flask/app.py:1891]
Traceback (most recent call last):
  File "/Users/markgetrost/.pyenv/versions/3.9.0/envs/venv390/lib/python3.9/site-packages/flask/app.py", line 2447, in wsgi_app
    response = self.full_dispatch_request()
  File "/Users/markgetrost/.pyenv/versions/3.9.0/envs/venv390/lib/python3.9/site-packages/flask/app.py", line 1953, in full_dispatch_request
    return self.finalize_request(rv)
  File "/Users/markgetrost/.pyenv/versions/3.9.0/envs/venv390/lib/python3.9/site-packages/flask/app.py", line 1968, in finalize_request
    response = self.make_response(rv)
  File "/Users/markgetrost/.pyenv/versions/3.9.0/envs/venv390/lib/python3.9/site-packages/flask/app.py", line 2097, in make_response
    raise TypeError(
TypeError: The view function did not return a valid response. The function either returned None or ended without a return statement.
2021-02-27 19:06:44,157 ERROR: Exception on /break_app [GET] [in /Users/markgetrost/.pyenv/versions/3.9.0/envs/venv390/lib/python3.9/site-packages/flask/app.py:1891]
Traceback (most recent call last):
  File "/Users/markgetrost/.pyenv/versions/3.9.0/envs/venv390/lib/python3.9/site-packages/flask/app.py", line 2447, in wsgi_app
    response = self.full_dispatch_request()
  File "/Users/markgetrost/.pyenv/versions/3.9.0/envs/venv390/lib/python3.9/site-packages/flask/app.py", line 1953, in full_dispatch_request
    return self.finalize_request(rv)
  File "/Users/markgetrost/.pyenv/versions/3.9.0/envs/venv390/lib/python3.9/site-packages/flask/app.py", line 1968, in finalize_request
    response = self.make_response(rv)
  File "/Users/markgetrost/.pyenv/versions/3.9.0/envs/venv390/lib/python3.9/site-packages/flask/app.py", line 2097, in make_response
    raise TypeError(
TypeError: The view function did not return a valid response. The function either returned None or ended without a return statement.
2021-02-27 19:57:44,946 INFO: Microblog startup [in /Users/markgetrost/Projects/FlaskMega/firstwebapp/app/__init__.py:61]
2021-02-27 20:19:31,133 INFO: Microblog startup [in /Users/markgetrost/Projects/FlaskMega/firstwebapp/app/__init__.py:61]
2021-02-27 20:45:48,862 INFO: Microblog startup [in /Users/markgetrost/Projects/FlaskMega/firstwebapp/app/__init__.py:61]
2021-02-27 20:45:53,618 ERROR: Exception on /user/markgetrost [GET] [in /Users/markgetrost/.pyenv/versions/3.9.0/envs/venv390/lib/python3.9/site-packages/flask/app.py:1891]
Traceback (most recent call last):
  File "/Users/markgetrost/.pyenv/versions/3.9.0/envs/venv390/lib/python3.9/site-packages/flask/app.py", line 2447, in wsgi_app
    response = self.full_dispatch_request()
  File "/Users/markgetrost/.pyenv/versions/3.9.0/envs/venv390/lib/python3.9/site-packages/flask/app.py", line 1952, in full_dispatch_request
    rv = self.handle_user_exception(e)
  File "/Users/markgetrost/.pyenv/versions/3.9.0/envs/venv390/lib/python3.9/site-packages/flask/app.py", line 1821, in handle_user_exception
    reraise(exc_type, exc_value, tb)
  File "/Users/markgetrost/.pyenv/versions/3.9.0/envs/venv390/lib/python3.9/site-packages/flask/_compat.py", line 39, in reraise
    raise value
  File "/Users/markgetrost/.pyenv/versions/3.9.0/envs/venv390/lib/python3.9/site-packages/flask/app.py", line 1950, in full_dispatch_request
    rv = self.dispatch_request()
  File "/Users/markgetrost/.pyenv/versions/3.9.0/envs/venv390/lib/python3.9/site-packages/flask/app.py", line 1936, in dispatch_request
    return self.view_functions[rule.endpoint](**req.view_args)
  File "/Users/markgetrost/.pyenv/versions/3.9.0/envs/venv390/lib/python3.9/site-packages/flask_login/utils.py", line 272, in decorated_view
    return func(*args, **kwargs)
  File "/Users/markgetrost/Projects/FlaskMega/firstwebapp/app/routes.py", line 186, in user
    return render_template('user.html',user=user,posts=posts.items,form=form)
  File "/Users/markgetrost/.pyenv/versions/3.9.0/envs/venv390/lib/python3.9/site-packages/flask/templating.py", line 137, in render_template
    return _render(
  File "/Users/markgetrost/.pyenv/versions/3.9.0/envs/venv390/lib/python3.9/site-packages/flask/templating.py", line 120, in _render
    rv = template.render(context)
  File "/Users/markgetrost/.pyenv/versions/3.9.0/envs/venv390/lib/python3.9/site-packages/jinja2/environment.py", line 1090, in render
    self.environment.handle_exception()
  File "/Users/markgetrost/.pyenv/versions/3.9.0/envs/venv390/lib/python3.9/site-packages/jinja2/environment.py", line 832, in handle_exception
    reraise(*rewrite_traceback_stack(source=source))
  File "/Users/markgetrost/.pyenv/versions/3.9.0/envs/venv390/lib/python3.9/site-packages/jinja2/_compat.py", line 28, in reraise
    raise value.with_traceback(tb)
  File "/Users/markgetrost/Projects/FlaskMega/firstwebapp/app/templates/user.html", line 1, in top-level template code
    {% extends "base.html" %}
  File "/Users/markgetrost/Projects/FlaskMega/firstwebapp/app/templates/base.html", line 1, in top-level template code
    {% extends 'bootstrap/base.html' %}
  File "/Users/markgetrost/.pyenv/versions/3.9.0/envs/venv390/lib/python3.9/site-packages/flask_bootstrap/templates/bootstrap/base.html", line 1, in top-level template code
    {% block doc -%}
  File "/Users/markgetrost/.pyenv/versions/3.9.0/envs/venv390/lib/python3.9/site-packages/flask_bootstrap/templates/bootstrap/base.html", line 4, in block "doc"
    {%- block html %}
  File "/Users/markgetrost/.pyenv/versions/3.9.0/envs/venv390/lib/python3.9/site-packages/flask_bootstrap/templates/bootstrap/base.html", line 20, in block "html"
    {% block body -%}
  File "/Users/markgetrost/.pyenv/versions/3.9.0/envs/venv390/lib/python3.9/site-packages/flask_bootstrap/templates/bootstrap/base.html", line 23, in block "body"
    {% block content -%}
  File "/Users/markgetrost/Projects/FlaskMega/firstwebapp/app/templates/base.html", line 42, in block "content"
    {% block app_content %}{% endblock %}
  File "/Users/markgetrost/Projects/FlaskMega/firstwebapp/app/templates/user.html", line 16, in block "app_content"
    <p>Last seen on: {{ moment(user.last_seen).format('LLL') }}</p>
jinja2.exceptions.UndefinedError: 'moment' is undefined
2021-02-27 20:48:29,719 INFO: Microblog startup [in /Users/markgetrost/Projects/FlaskMega/firstwebapp/app/__init__.py:62]
